Workbook

Sheet 5_Resumo
A1: RESULTADO CONSOLIDADO (12 meses) — v4
A2: Serviço | B2: Receita Total | C2: Total Custos | D2: Margem R$ | E2: Margem % | F2: Preço ideal 30%
A3: Expansão | B3: 1323600 | C3: 549988 | D3: 773612 | E3: 0.58447567 | F3: 3832.669
A4: Formatação | B4: 2932500 | C4: 1469628 | D4: 1462872 | E4: 0.49884808 | F4: 43738.929
A5: Validação | B5: 306900 | C5: 330038 | D5: -23138 | E5: -0.075392636 | F5: 15209.124
A6: TOTAL | B6: 4563000 | C6: 2349654 | D6: 2213346 | E6: 0.48506377 | F6: —

Sheet 1_Base_Mensal_v4
A1: IDENTIFICAÇÃO | D1: RECEITA | G1: HORAS | L1: CUSTOS PESSOAL | Q1: CUSTOS OPERACIONAIS | Z1: RESULTADO
A2: Mês | B2: Franquia | C2: Serviço | D2: Preço Unit. | E2: Qtd | F2: Receita | G2: H_SDR | H2: H_Vend | I2: H_Cons | J2: H_GP | K2: H_Adv | L2: C_SDR | M2: C_Vend | N2: C_Cons | O2: C_CEO | P2: C_Ext | Q2: C_CAC | R2: C_Agenc | S2: C_Jur | T2: C_Contab | U2: C_GP | V2: C_Tec | W2: C_Mkt | X2: C_Tel | Y2: C_Desl | Z2: C_Trein | AA2: C_Imp | AB2: C_Com | AC2: Total Custos | AD2: Margem R$ | AE2: Margem %
A3: 2024-01 | B3: Cogni Academy | C3: Expansão | D3: 5400 | E3: 4 | F3: 21600 | G3: 151 | H3: 81 | I3: 42 | J3: 0 | K3: 0 | L3: 1036 | M3: 1036 | N3: 1250 | O3: 833 | P3: 250 | Q3: 0 | R3: - | S3: 0 | T3: 0 | U3: 0 | V3: 1093 | W3: 155 | X3: 411 | Y3: 622 | Z3: 125 | AA3: 1296 | AB3: 1080 | AC3: 10233 | AD3: 11367 | AE3: 0.52625
A4: 2024-01 | B4: Cogni Academy | C4: Formatação | D4: 69000 | E4: 1 | F4: 69000 | G4: 8 | H4: 9 | I4: 110 | J4: 0 | K4: 17 | L4: 1073 | M4: 1073 | N4: 7812 | O4: 833 | P4: 250 | Q4: 6098 | R4: 5417 | S4: 3740 | T4: 2080 | U4: 0 | V4: 1132 | W4: 161 | X4: 426 | Y4: 161 | Z4: 250 | AA4: 4140 | AB4: 3450 | AC4: 32679 | AD4: 36321 | AE4: 0.5263913
A5: 2024-01 | B5: Clínica da Cidade | C5: Expansão | D5: 10000 | E5: 4 | F5: 40000 | G5: 171 | H5: 82 | I5: 42 | J5: 0 | K5: 0 | L5: 902 | M5: 902 | N5: 1250 | O5: 833 | P5: 250 | Q5: 0 | R5: - | S5: 0 | T5: 0 | U5: 0 | V5: 952 | W5: 135 | X5: 358 | Y5: 541 | Z5: 125 | AA5: 2400 | AB5: 2000 | AC5: 12538 | AD5: 27462 | AE5: 0.68655
A6: 2024-01 | B6: Clínica da Cidade | C6: Formatação | D6: 103500 | E6: 1 | F6: 103500 | G6: 5 | H6: 10 | I6: 108 | J6: 0 | K6: 31 | L6: 1009 | M6: 1009 | N6: 7670 | O6: 833 | P6: 250 | Q6: 7098 | R6: 5938 | S6: 6820 | T6: 2080 | U6: 0 | V6: 1064 | W6: 151 | X6: 400 | Y6: 151 | Z6: 250 | AA6: 6210 | AB6: 5175 | AC6: 40170 | AD6: 63330 | AE6: 0.61188406
A7: 2024-01 | B7: Clínica da Cidade | C7: Validação | D7: 9900 | E7: 1 | F7: 9900 | G7: 0 | H7: 7 | I7: 29 | J7: 12 | K7: 0 | L7: 0 | M7: 1087 | N7: 2060 | O7: 833 | P7: 250 | Q7: 0 | R7: 5551 | S7: 0 | T7: 694 | U7: 3000 | V7: 1147 | W7: - | X7: - | Y7: - | Z7: - | AA7: 594 | AB7: 495 | AC7: =SUM(M7:AB7) -> 15711 | AD7: =F7-AC7 -> -5811 | AE7: =AD7/F7 -> -0.5869697
A8: 2024-01 | B8: Smart Nutri | C8: Expansão | D8: 10000 | E8: 4 | F8: 40000 | G8: 153 | H8: 82 | I8: 39 | J8: 0 | K8: 0 | L8: 936 | M8: 936 | N8: 1250 | O8: 833 | P8: 250 | Q8: 0 | R8: - | S8: 0 | T8: 0 | U8: 0 | V8: 987 | W8: 140 | X8: - | Y8: - | Z8: - | AA8: 2400 | AB8: 2000 | AC8: 12247 | AD8: 27753 | AE8: 0.15348485
A9: 2024-01 | B9: Smart Nutri | C9: Formatação | D9: 34500 | E9: 1 | F9: 34500 | G9: 9 | H9: 10 | I9: 103 | J9: 0 | K9: 9 | L9: 930 | M9: 930 | N9: 7315 | O9: 833 | P9: 250 | Q9: 5098 | R9: 5903 | S9: 1980 | T9: 2080 | U9: 0 | V9: 981 | W9: 140 | X9: 385 | Y9: 145 | Z9: 250 | AA9: 2070 | AB9: 1725 | AC9: 25091 | AD9: 9409 | AE9: -0.56494949
A10: 2024-01 | B10: EduKids Brasil | C10: Expansão | D10: 8000 | E10: 4 | F10: 32000 | G10: 156 | H10: 88 | I10: 41 | J10: 0 | K10: 0 | L10: 1055 | M10: 1055 | N10: 1250 | O10: 833 | P10: 250 | Q10: 0 | R10: - | S10: 0 | T10: 0 | U10: 0 | V10: 1113 | W10: 158 | X10: - | Y10: - | Z10: - | AA10: 1920 | AB10: 1600 | AC10: 12347 | AD10: 19653 | AE10: 0.16348485
A11: 2024-01 | B11: EduKids Brasil | C11: Formatação | D11: 69000 | E11: 1 | F11: 69000 | G11: 8 | H11: 9 | I11: 92 | J11: 0 | K11: 17 | L11: 1044 | M11: 1044 | N11: 6534 | O11: 833 | P11: 250 | Q11: 6098 | R11: 5445 | S11: 3740 | T11: 2080 | U11: 0 | V11: 1102 | W11: 157 | X11: 355 | Y11: 134 | Z11: 250 | AA11: 4140 | AB11: 3450 | AC11: 31294 | AD11: 37706 | AE11: -0.60666667
A12: 2024-01 | B12: EduKids Brasil | C12: Validação | D12: 9900 | E12: 2 | F12: 19800 | G12: 0 | H12: 17 | I12: 60 | J12: 43 | K12: 0 | L12: 0 | M12: 944 | N12: 3125 | O12: 833 | P12: 250 | Q12: 0 | R12: 6588 | S12: 0 | T12: 347 | U12: 1500 | V12: 996 | W12: - | X12: - | Y12: - | Z12: - | AA12: 1188 | AB12: 990 | AC12: =SUM(M12:AB12) -> 16761 | AD12: =F12-AC12 -> 3039 | AE12: =AD12/F12 -> 0.15348485
A13: 2024-02 | B13: Cogni Academy | C13: Expansão | D13: 8000 | E13: 4 | F13: 32000 | G13: 166 | H13: 82 | I13: 39 | J13: 0 | K13: 0 | L13: 917 | M13: 917 | N13: 1250 | O13: 833 | P13: 250 | Q13: 0 | R13: - | S13: 0 | T13: 0 | U13: 0 | V13: 967 | W13: 138 | X13: - | Y13: - | Z13: - | AA13: 1920 | AB13: 1600 | AC13: 11567 | AD13: 20433 | AE13: -0.56828283
A14: 2024-02 | B14: Cogni Academy | C14: Formatação | D14: 34500 | E14: 1 | F14: 34500 | G14: 8 | H14: 11 | I14: 105 | J14: 0 | K14: 8 | L14: 992 | M14: 992 | N14: 7457 | O14: 833 | P14: 250 | Q14: 5098 | R14: 5224 | S14: 1760 | T14: 2080 | U14: 0 | V14: 1047 | W14: 149 | X14: 374 | Y14: 141 | Z14: 250 | AA14: 2070 | AB14: 1725 | AC14: 25246 | AD14: 9254 | AE14: -0.56535354
A15: 2024-02 | B15: Clínica da Cidade | C15: Expansão | D15: 4500 | E15: 4 | F15: 18000 | G15: 169 | H15: 77 | I15: 38 | J15: 0 | K15: 0 | L15: 1092 | M15: 1092 | N15: 1250 | O15: 833 | P15: 250 | Q15: 0 | R15: - | S15: 0 | T15: 0 | U15: 0 | V15: 1152 | W15: 164 | X15: - | Y15: - | Z15: - | AA15: 1080 | AB15: 900 | AC15: 10378 | AD15: 7622 | AE15: 0.15262626
A16: 2024-02 | B16: Clínica da Cidade | C16: Formatação | D16: 69000 | E16: 1 | F16: 69000 | G16: 7 | H16: 11 | I16: 106 | J16: 0 | K16: 18 | L16: 881 | M16: 881 | N16: 7528 | O16: 833 | P16: 250 | Q16: 6098 | R16: 5691 | S16: 3960 | T16: 2080 | U16: 0 | V16: 929 | W16: 132 | X16: 394 | Y16: 149 | Z16: 250 | AA16: 4140 | AB16: 3450 | AC16: 31894 | AD16: 37106 | AE16: -0.6040404
A17: 2024-02 | B17: Clínica da Cidade | C17: Validação | D17: 9900 | E17: 1 | F17: 9900 | G17: 0 | H17: 8 | I17: 29 | J17: 14 | K17: 0 | L17: 0 | M17: 906 | N17: 2060 | O17: 833 | P17: 250 | Q17: 0 | R17: 5706 | S17: 0 | T17: 694 | U17: 3000 | V17: 955 | W17: - | X17: - | Y17: - | Z17: - | AA17: 594 | AB17: 495 | AC17: =SUM(M17:AB17) -> 15493 | AD17: =F17-AC17 -> -5593 | AE17: =AD17/F17 -> -0.56494949
A18: 2024-02 | B18: Smart Nutri | C18: Expansão | D18: 3000 | E18: 4 | F18: 12000 | G18: 173 | H18: 82 | I18: 40 | J18: 0 | K18: 0 | L18: 1109 | M18: 1109 | N18: 1250 | O18: 833 | P18: 250 | Q18: 0 | R18: - | S18: 0 | T18: 0 | U18: 0 | V18: 1170 | W18: 166 | X18: - | Y18: - | Z18: - | AA18: 720 | AB18: 600 | AC18: 9732 | AD18: 2268 | AE18: -0.59858586
A19: 2024-02 | B19: Smart Nutri | C19: Formatação | D19: 103500 | E19: 1 | F19: 103500 | G19: 3 | H19: 9 | I19: 96 | J19: 0 | K19: 31 | L19: 967 | M19: 967 | N19: 6818 | O19: 833 | P19: 250 | Q19: 7098 | R19: 5604 | S19: 6820 | T19: 2080 | U19: 0 | V19: 1020 | W19: 145 | X19: 368 | Y19: 139 | Z19: 250 | AA19: 6210 | AB19: 5175 | AC19: 39162 | AD19: 64338 | AE19: -0.59535354
A20: 2024-02 | B20: EduKids Brasil | C20: Expansão | D20: 4500 | E20: 4 | F20: 18000 | G20: 170 | H20: 88 | I20: 40 | J20: 0 | K20: 0 | L20: 899 | M20: 899 | N20: 1250 | O20: 833 | P20: 250 | Q20: 0 | R20: - | S20: 0 | T20: 0 | U20: 0 | V20: 948 | W20: 135 | X20: - | Y20: - | Z20: - | AA20: 1080 | AB20: 900 | AC20: 9283 | AD20: 8717 | AE20: -0.59353535
A21: 2024-02 | B21: EduKids Brasil | C21: Formatação | D21: 103500 | E21: 1 | F21: 103500 | G21: 6 | H21: 10 | I21: 103 | J21: 0 | K21: 35 | L21: 1038 | M21: 1038 | N21: 7315 | O21: 833 | P21: 250 | Q21: 7098 | R21: 5915 | S21: 7700 | T21: 2080 | U21: 0 | V21: 1095 | W21: 156 | X21: 358 | Y21: 135 | Z21: 250 | AA21: 6210 | AB21: 5175 | AC21: 40806 | AD21: 62694 | AE21: -0.59272727
A22: 2024-03 | B22: Cogni Academy | C22: Expansão | D22: 4500 | E22: 5 | F22: 22500 | G22: 176 | H22: 91 | I22: 45 | J22: 0 | K22: 0 | L22: 882 | M22: 882 | N22: 1250 | O22: 833 | P22: 250 | Q22: 0 | R22: - | S22: 0 | T22: 0 | U22: 0 | V22: 930 | W22: 132 | X22: - | Y22: - | Z22: - | AA22: 1350 | AB22: 1125 | AC22: 10089 | AD22: 12411 | AE22: 0.17116162
A23: 2024-03 | B23: Cogni Academy | C23: Formatação | D23: 34500 | E23: 1 | F23: 34500 | G23: 0 | H23: 10 | I23: 106 | J23: 0 | K23: 12 | L23: 1003 | M23: 1003 | N23: 7528 | O23: 833 | P23: 250 | Q23: 5098 | R23: 5659 | S23: 2640 | T23: 2080 | U23: 0 | V23: 1059 | W23: 151 | X23: 355 | Y23: 134 | Z23: 250 | AA23: 2070 | AB23: 1725 | AC23: 26239 | AD23: 8261 | AE23: 0.1329798
A24: 2024-03 | B24: Cogni Academy | C24: Validação | D24: 9900 | E24: 2 | F24: 19800 | G24: 0 | H24: 16 | I24: 57 | J24: 43 | K24: 0 | L24: 0 | M24: 1018 | N24: 3125 | O24: 833 | P24: 250 | Q24: 0 | R24: 6238 | S24: 0 | T24: 347 | U24: 1500 | V24: 1074 | W24: - | X24: - | Y24: - | Z24: - | AA24: 1188 | AB24: 990 | AC24: =SUM(M24:AB24) -> 16563 | AD24: =F24-AC24 -> 3237 | AE24: =AD24/F24 -> 0.16348485
A25: 2024-03 | B25: Clínica da Cidade | C25: Expansão | D25: 4500 | E25: 4 | F25: 18000 | G25: 146 | H25: 82 | I25: 41 | J25: 0 | K25: 0 | L25: 979 | M25: 979 | N25: 1250 | O25: 833 | P25: 250 | Q25: 0 | R25: - | S25: 0 | T25: 0 | U25: 0 | V25: 1032 | W25: 147 | X25: - | Y25: - | Z25: - | AA25: 1080 | AB25: 900 | AC25: 9619 | AD25: 8381 | AE25: -0.62767677
A26: 2024-03 | B26: Clínica da Cidade | C26: Formatação | D26: 69000 | E26: 1 | F26: 69000 | G26: 7 | H26: 9 | I26: 102 | J26: 0 | K26: 16 | L26: 1055 | M26: 1055 | N26: 7244 | O26: 833 | P26: 250 | Q26: 6098 | R26: 5885 | S26: 3520 | T26: 2080 | U26: 0 | V26: 1113 | W26: 158 | X26: 404 | Y26: 153 | Z26: 250 | AA26: 4140 | AB26: 3450 | AC26: 31823 | AD26: 37177 | AE26: -0.54828283
A27: 2024-03 | B27: Clínica da Cidade | C27: Validação | D27: 9900 | E27: 1 | F27: 9900 | G27: 0 | H27: 7 | I27: 33 | J27: 26 | K27: 0 | L27: 0 | M27: 924 | N27: 2344 | O27: 833 | P27: 250 | Q27: 0 | R27: 5797 | S27: 0 | T27: 694 | U27: 3000 | V27: 975 | W27: - | X27: - | Y27: - | Z27: - | AA27: 594 | AB27: 495 | AC27: =SUM(M27:AB27) -> 15906 | AD27: =F27-AC27 -> -6006 | AE27: =AD27/F27 -> -0.60666667
A28: 2024-03 | B28: Smart Nutri | C28: Expansão | D28: 5400 | E28: 5 | F28: 27000 | G28: 176 | H28: 92 | I28: 53 | J28: 0 | K28: 0 | L28: 1037 | M28: 1037 | N28: 1250 | O28: 833 | P28: 250 | Q28: 0 | R28: - | S28: 0 | T28: 0 | U28: 0 | V28: 1094 | W28: 155 | X28: - | Y28: - | Z28: - | AA28: 1620 | AB28: 1350 | AC28: 11343 | AD28: 15657 | AE28: -0.49484848
A29: 2024-03 | B29: Smart Nutri | C29: Formatação | D29: 34500 | E29: 1 | F29: 34500 | G29: 0 | H29: 11 | I29: 94 | J29: 0 | K29: 8 | L29: 978 | M29: 978 | N29: 6676 | O29: 833 | P29: 250 | Q29: 5098 | R29: 5732 | S29: 1760 | T29: 2080 | U29: 0 | V29: 1031 | W29: 147 | X29: 433 | Y29: 163 | Z29: 250 | AA29: 2070 | AB29: 1725 | AC29: 24411 | AD29: 10089 | AE29: -0.58242424
A30: 2024-03 | B30: EduKids Brasil | C30: Expansão | D30: 3000 | E30: 4 | F30: 12000 | G30: 169 | H30: 77 | I30: 42 | J30: 0 | K30: 0 | L30: 974 | M30: 974 | N30: 1250 | O30: 833 | P30: 250 | Q30: 0 | R30: - | S30: 0 | T30: 0 | U30: 0 | V30: 1027 | W30: 146 | X30: - | Y30: - | Z30: - | AA30: 720 | AB30: 600 | AC30: 9911 | AD30: 2089 | AE30: -0.5740404
A31: 2024-03 | B31: EduKids Brasil | C31: Formatação | D31: 69000 | E31: 1 | F31: 69000 | G31: 7 | H31: 9 | I31: 95 | J31: 0 | K31: 15 | L31: 1068 | M31: 1068 | N31: 6747 | O31: 833 | P31: 250 | Q31: 6098 | R31: 5442 | S31: 3300 | T31: 2080 | U31: 0 | V31: 1127 | W31: 160 | X31: 385 | Y31: 146 | Z31: 250 | AA31: 4140 | AB31: 3450 | AC31: 31155 | AD31: 37845 | AE31: -0.63808081
A32: 2024-04 | B32: Cogni Academy | C32: Expansão | D32: 5400 | E32: 4 | F32: 21600 | G32: 163 | H32: 73 | I32: 37 | J32: 0 | K32: 0 | L32: 1106 | M32: 1106 | N32: 1250 | O32: 833 | P32: 250 | Q32: 0 | R32: - | S32: 0 | T32: 0 | U32: 0 | V32: 1167 | W32: 166 | X32: - | Y32: - | Z32: - | AA32: 1296 | AB32: 1080 | AC32: 11679 | AD32: 9921 | AE32: -0.62464646
A33: 2024-04 | B33: Cogni Academy | C33: Formatação | D33: 34500 | E33: 1 | F33: 34500 | G33: 8 | H33: 10 | I33: 97 | J33: 0 | K33: 9 | L33: 1016 | M33: 1016 | N33: 6889 | O33: 833 | P33: 250 | Q33: 5098 | R33: 5228 | S33: 1980 | T33: 2080 | U33: 0 | V33: 1072 | W33: 152 | X33: 403 | Y33: 152 | Z33: 250 | AA33: 2070 | AB33: 1725 | AC33: 24986 | AD33: 9514 | AE33: 0.27576812
A34: 2024-04 | B34: Clínica da Cidade | C34: Expansão | D34: 5400 | E34: 4 | F34: 21600 | G34: 159 | H34: 87 | I34: 43 | J34: 0 | K34: 0 | L34: 911 | M34: 911 | N34: 1250 | O34: 833 | P34: 250 | Q34: 0 | R34: - | S34: 0 | T34: 0 | U34: 0 | V34: 962 | W34: 137 | X34: 362 | Y34: 547 | Z34: 125 | AA34: 1296 | AB34: 1080 | AC34: 9588 | AD34: 12012 | AE34: 0.55611111
A35: 2024-04 | B35: Clínica da Cidade | C35: Formatação | D35: 69000 | E35: 1 | F35: 69000 | G35: 7 | H35: 10 | I35: 101 | J35: 0 | K35: 16 | L35: 1029 | M35: 1029 | N35: 7173 | O35: 833 | P35: 250 | Q35: 6098 | R35: 5372 | S35: 3520 | T35: 2080 | U35: 0 | V35: 1086 | W35: 154 | X35: 409 | Y35: 154 | Z35: 250 | AA35: 4140 | AB35: 3450 | AC35: 31655 | AD35: 37345 | AE35: 0.54123188
A36: 2024-04 | B36: Smart Nutri | C36: Expansão | D36: 10000 | E36: 4 | F36: 40000 | G36: 152 | H36: 77 | I36: 40 | J36: 0 | K36: 0 | L36: 964 | M36: 964 | N36: 1250 | O36: 833 | P36: 250 | Q36: 0 | R36: - | S36: 0 | T36: 0 | U36: 0 | V36: 1017 | W36: 145 | X36: 383 | Y36: 578 | Z36: 125 | AA36: 2400 | AB36: 2000 | AC36: 12658 | AD36: 27342 | AE36: 0.68355
A37: 2024-04 | B37: Smart Nutri | C37: Formatação | D37: 103500 | E37: 1 | F37: 103500 | G37: 8 | H37: 10 | I37: 104 | J37: 0 | K37: 31 | L37: 953 | M37: 953 | N37: 7386 | O37: 833 | P37: 250 | Q37: 7098 | R37: 5573 | S37: 6820 | T37: 2080 | U37: 0 | V37: 1005 | W37: 143 | X37: 378 | Y37: 143 | Z37: 250 | AA37: 6210 | AB37: 5175 | AC37: 39677 | AD37: 63823 | AE37: 0.61664734
A38: 2024-04 | B38: EduKids Brasil | C38: Expansão | D38: 10000 | E38: 4 | F38: 40000 | G38: 172 | H38: 76 | I38: 43 | J38: 0 | K38: 0 | L38: 1104 | M38: 1104 | N38: 1250 | O38: 833 | P38: 250 | Q38: 0 | R38: - | S38: 0 | T38: 0 | U38: 0 | V38: 1164 | W38: 166 | X38: 438 | Y38: 662 | Z38: 125 | AA38: 2400 | AB38: 2000 | AC38: 13829 | AD38: 26171 | AE38: 0.654275
A39: 2024-04 | B39: EduKids Brasil | C39: Formatação | D39: 34500 | E39: 1 | F39: 34500 | G39: 4 | H39: 10 | I39: 105 | J39: 0 | K39: 11 | L39: 917 | M39: 917 | N39: 7457 | O39: 833 | P39: 250 | Q39: 5098 | R39: 5415 | S39: 2420 | T39: 2080 | U39: 0 | V39: 968 | W39: 138 | X39: 364 | Y39: 138 | Z39: 250 | AA39: 2070 | AB39: 1725 | AC39: 25625 | AD39: 8875 | AE39: 0.25724638
A40: 2024-05 | B40: Cogni Academy | C40: Expansão | D40: 3000 | E40: 4 | F40: 12000 | G40: 166 | H40: 74 | I40: 36 | J40: 0 | K40: 0 | L40: 907 | M40: 907 | N40: 1250 | O40: 833 | P40: 250 | Q40: 0 | R40: - | S40: 0 | T40: 0 | U40: 0 | V40: 957 | W40: 136 | X40: 360 | Y40: 544 | Z40: 125 | AA40: 720 | AB40: 600 | AC40: 8998 | AD40: 3002 | AE40: 0.25016667
...

Sheet 2_Premissas_v4
A1: PREMISSAS VIGENTES — v4
A2: Parâmetro | B2: Valor
A3: Horas úteis/mês | B3: 176
A4: Salário Consultor PJ (Format.+Valid.) | B4: 12500
A5: % horas consultor → Formatação | B5: 75%
A6: % horas consultor → Validação | B6: 25%
A7: Custo/hora consultor | B7: R$ 71,02/h
A8: Custo/hora advogado PJ | B8: R$ 220,00/h
A9: Salário GP (fixo mensal, só Valid.) | B9: R$ 3.000
A10: Contabilidade mensal (Format.+Valid.) | B10: R$ 2.774
A11: Contabilidade → Formatação (75%) | B11: R$ 2.080/mês
A12: Contabilidade → Validação (25%) | B12: R$ 694/mês
A14: CAC FORMATAÇÃO POR TIER
A15: Tier R$34.500 | B15: R$ 5.098/contrato
A16: Tier R$69.000 | B16: R$ 6.098/contrato
A17: Tier R$103.500 | B17: R$ 7.098/contrato
A19: HORAS ADVOGADO POR TIER (Formatação)
A20: Tier R$34.500 | B20: 8 a 12h/contrato
A21: Tier R$69.000 | B21: 15 a 20h/contrato
A22: Tier R$103.500 | B22: 25 a 35h/contrato
A24: VALIDAÇÃO — AJUSTES v4
A25: Custo SDR | B25: R$ 0 (sem SDR nessa fase)
A26: Horas GP por contrato | B26: 5h a 30h (driver de complexidade)
A27: GP entra na regressão? | B27: Não — custo fixo rateado
A28: Alíquota imposto | B28: 6,0%
A29: Comissão vendas | B29: 5,0%

Sheet 3_Resultados_v4
A1: RESULTADOS DOS MODELOS DE REGRESSÃO — v4
A2: Serviço | B2: R² | C2: R²aj | D2: F (p-val) | E2: MAE (R$) | F2: Custo/contrato | G2: Breakeven | H2: Preço ideal 30%
A3: Expansão | B3: 0.098 | C3: 0.037 | D3: 1.6 (p=0.2033) | E3: R$1,071 | F3: R$2,683 | G3: R$2,683 | H3: R$3,833
A4: Formatação | B4: 0.951 | C4: 0.947 | D4: 282.4 (p=0.0000) | E4: R$889 | F4: R$30,617 | G4: R$30,617 | H4: R$43,739
A5: Validação | B5: 0.208 | C5: 0.100 | D5: 1.9 (p=0.1550) | E5: R$437 | F5: R$10,646 | G5: R$10,646 | H5: R$15,209
A6: COEFICIENTES β — MODELO 1 (Y = Custo Total)
A7: Serviço | B7: Variável | C7: β | D7: p-valor | E7: Sig. | F7: Elasticidade
A8: Expansão | B8: const | C8: 7354.25 | D8: 0.046 | E8: ** | F8: —
B9: Qtd_Contratos | C9: 240.84 | D9: 0.758 | E9: ns | F9: 0.09
B10: H_Total | C10: 12.48 | D10: 0.647 | E10: ns | F10: 0.227
B11: Num_Mes | C11: 72.2 | D11: 0.245 | E11: ns | F11: 0.041
A13: Formatação | B13: const | C13: 7029.42 | D13: 0 | E13: *** | F13: —
B14: Qtd_Contratos | C14: 7029.42 | D14: 0 | E14: *** | F14: 0.23
B15: H_Total | C15: 45.57 | D15: 0.061 | E15: * | F15: 0.159
B16: H_Advogado | C16: 686.23 | D16: 0 | E16: *** | F16: 0.37
B17: Num_Mes | C17: 56.02 | D17: 0.244 | E17: ns | F17: 0.012
A19: Validação | B19: const | C19: 11551.5 | D19: 0 | E19: *** | F19: —
B20: Qtd_Contratos | C20: -498.03 | D20: 0.793 | E20: ns | F20: -0.047
B21: H_Total | C21: 40.98 | D21: 0.524 | E21: ns | F21: 0.117
B22: Num_Mes | C22: 32.24 | D22: 0.372 | E22: ns | F22: 0.02

Sheet Planilha3
A1: Mês | B1: Franquia | C1: Serviço | D1: Preço Unit. | E1: Qtd | F1: Receita | G1: H_SDR | H1: H_Vend | I1: H_Cons | J1: H_GP | K1: H_Adv | L1: C_SDR | M1: C_Vend | N1: C_Cons | O1: C_CEO | P1: C_Ext | Q1: C_CAC | R1: C_Agenc | S1: C_Jur | T1: C_Contab | U1: C_GP | V1: C_Tec | W1: C_Mkt | X1: C_Tel | Y1: C_Desl | Z1: C_Trein | AA1: C_Imp | AB1: C_Com | AC1: Total Custos | AD1: Margem R$ | AE1: Margem %
A2: 2024-01 | B2: Cogni Academy | C2: Expansão | D2: 5400 | E2: 4 | F2: 21600 | G2: 151 | H2: 81 | I2: 42 | J2: 0 | K2: 0 | L2: 1036 | M2: 1036 | N2: 1250 | O2: 833 | P2: 250 | Q2: 0 | R2: - | S2: 0 | T2: 0 | U2: 0 | V2: 1093 | W2: 155 | X2: 411 | Y2: 622 | Z2: 125 | AA2: 1296 | AB2: 1080 | AC2: 10233 | AD2: 11367 | AE2: 0.52625
A3: 2024-01 | B3: Clínica da Cidade | C3: Expansão | D3: 10000 | E3: 4 | F3: 40000 | G3: 171 | H3: 82 | I3: 42 | J3: 0 | K3: 0 | L3: 902 | M3: 902 | N3: 1250 | O3: 833 | P3: 250 | Q3: 0 | R3: - | S3: 0 | T3: 0 | U3: 0 | V3: 952 | W3: 135 | X3: 358 | Y3: 541 | Z3: 125 | AA3: 2400 | AB3: 2000 | AC3: 12538 | AD3: 27462 | AE3: 0.68655
A4: 2024-01 | B4: Smart Nutri | C4: Expansão | D4: 10000 | E4: 4 | F4: 40000 | G4: 153 | H4: 82 | I4: 39 | J4: 0 | K4: 0 | L4: 936 | M4: 936 | N4: 1250 | O4: 833 | P4: 250 | Q4: 0 | R4: - | S4: 0 | T4: 0 | U4: 0 | V4: 987 | W4: 140 | X4: 372 | Y4: 562 | Z4: 125 | AA4: 2400 | AB4: 2000 | AC4: 12247 | AD4: 27753 | AE4: 0.15348485
A5: 2024-01 | B5: EduKids Brasil | C5: Expansão | D5: 8000 | E5: 4 | F5: 32000 | G5: 156 | H5: 88 | I5: 41 | J5: 0 | K5: 0 | L5: 1055 | M5: 1055 | N5: 1250 | O5: 833 | P5: 250 | Q5: 0 | R5: - | S5: 0 | T5: 0 | U5: 0 | V5: 1113 | W5: 158 | X5: 419 | Y5: 633 | Z5: 125 | AA5: 1920 | AB5: 1600 | AC5: 12347 | AD5: 19653 | AE5: 0.16348485
A6: 2024-02 | B6: Cogni Academy | C6: Expansão | D6: 8000 | E6: 4 | F6: 32000 | G6: 166 | H6: 82 | I6: 39 | J6: 0 | K6: 0 | L6: 917 | M6: 917 | N6: 1250 | O6: 833 | P6: 250 | Q6: 0 | R6: - | S6: 0 | T6: 0 | U6: 0 | V6: 967 | W6: 138 | X6: 364 | Y6: 550 | Z6: 125 | AA6: 1920 | AB6: 1600 | AC6: 11567 | AD6: 20433 | AE6: -0.56828283
A7: 2024-02 | B7: Clínica da Cidade | C7: Expansão | D7: 4500 | E7: 4 | F7: 18000 | G7: 169 | H7: 77 | I7: 38 | J7: 0 | K7: 0 | L7: 1092 | M7: 1092 | N7: 1250 | O7: 833 | P7: 250 | Q7: 0 | R7: - | S7: 0 | T7: 0 | U7: 0 | V7: 1152 | W7: 164 | X7: 434 | Y7: 655 | Z7: 125 | AA7: 1080 | AB7: 900 | AC7: 10378 | AD7: 7622 | AE7: 0.15262626
A8: 2024-02 | B8: Smart Nutri | C8: Expansão | D8: 3000 | E8: 4 | F8: 12000 | G8: 173 | H8: 82 | I8: 40 | J8: 0 | K8: 0 | L8: 1109 | M8: 1109 | N8: 1250 | O8: 833 | P8: 250 | Q8: 0 | R8: - | S8: 0 | T8: 0 | U8: 0 | V8: 1170 | W8: 166 | X8: 440 | Y8: 665 | Z8: 125 | AA8: 720 | AB8: 600 | AC8: 9732 | AD8: 2268 | AE8: -0.59858586
A9: 2024-02 | B9: EduKids Brasil | C9: Expansão | D9: 4500 | E9: 4 | F9: 18000 | G9: 170 | H9: 88 | I9: 40 | J9: 0 | K9: 0 | L9: 899 | M9: 899 | N9: 1250 | O9: 833 | P9: 250 | Q9: 0 | R9: - | S9: 0 | T9: 0 | U9: 0 | V9: 948 | W9: 135 | X9: 357 | Y9: 539 | Z9: 125 | AA9: 1080 | AB9: 900 | AC9: 9283 | AD9: 8717 | AE9: -0.59353535
A10: 2024-03 | B10: Cogni Academy | C10: Expansão | D10: 4500 | E10: 5 | F10: 22500 | G10: 176 | H10: 91 | I10: 45 | J10: 0 | K10: 0 | L10: 882 | M10: 882 | N10: 1250 | O10: 833 | P10: 250 | Q10: 0 | R10: - | S10: 0 | T10: 0 | U10: 0 | V10: 930 | W10: 132 | X10: 350 | Y10: 661 | Z10: 125 | AA10: 1350 | AB10: 1125 | AC10: 10089 | AD10: 12411 | AE10: 0.17116162
A11: 2024-03 | B11: Clínica da Cidade | C11: Expansão | D11: 4500 | E11: 4 | F11: 18000 | G11: 146 | H11: 82 | I11: 41 | J11: 0 | K11: 0 | L11: 979 | M11: 979 | N11: 1250 | O11: 833 | P11: 250 | Q11: 0 | R11: - | S11: 0 | T11: 0 | U11: 0 | V11: 1032 | W11: 147 | X11: 389 | Y11: 587 | Z11: 125 | AA11: 1080 | AB11: 900 | AC11: 9619 | AD11: 8381 | AE11: -0.62767677
A12: 2024-03 | B12: Smart Nutri | C12: Expansão | D12: 5400 | E12: 5 | F12: 27000 | G12: 176 | H12: 92 | I12: 53 | J12: 0 | K12: 0 | L12: 1037 | M12: 1037 | N12: 1250 | O12: 833 | P12: 250 | Q12: 0 | R12: - | S12: 0 | T12: 0 | U12: 0 | V12: 1094 | W12: 155 | X12: 411 | Y12: 777 | Z12: 125 | AA12: 1620 | AB12: 1350 | AC12: 11343 | AD12: 15657 | AE12: -0.49484848
A13: 2024-03 | B13: EduKids Brasil | C13: Expansão | D13: 3000 | E13: 4 | F13: 12000 | G13: 169 | H13: 77 | I13: 42 | J13: 0 | K13: 0 | L13: 974 | M13: 974 | N13: 1250 | O13: 833 | P13: 250 | Q13: 0 | R13: - | S13: 0 | T13: 0 | U13: 0 | V13: 1027 | W13: 146 | X13: 387 | Y13: 584 | Z13: 125 | AA13: 720 | AB13: 600 | AC13: 9911 | AD13: 2089 | AE13: -0.5740404
... A49: 2024-12 | B49: EduKids Brasil | C49: Expansão | D49: 4500 | E49: 4 | F49: 18000 | G49: 163 | H49: 78 | I49: 41 | J49: 0 | K49: 0 | L49: 949 | M49: 949 | N49: 1250 | O49: 833 | P49: 250 | Q49: 0 | R49: - | S49: 0 | T49: 0 | U49: 0 | V49: 1001 | W49: 142 | X49: 377 | Y49: 569 | Z49: 125 | AA49: 1080 | AB49: 900 | AC49: 10257 | AD49: 7743 | AE49: -0.62464646

Sheet Planilha1
A1: Mês | B1: Franquia | C1: Serviço | D1: Preço Unit. | E1: Qtd | F1: Receita | G1: H_SDR | H1: H_Vend | I1: H_Cons | J1: H_GP | K1: H_Adv | L1: C_SDR | M1: C_Vend | N1: C_Cons | O1: C_CEO | P1: C_Ext | Q1: C_CAC | R1: C_Agenc | S1: C_Jur | T1: C_Contab | U1: C_GP | V1: C_Tec | W1: C_Mkt | X1: C_Tel | Y1: C_Desl | Z1: C_Trein | AA1: C_Imp | AB1: C_Com | AC1: Total Custos | AD1: Margem R$ | AE1: Margem %
A2: 2024-01 | B2: Clínica da Cidade | C2: Validação | D2: 9900 | E2: 1 | F2: 9900 | G2: 0 | H2: 7 | I2: 29 | J2: 12 | K2: 0 | L2: 0 | M2: 1087 | N2: 2060 | O2: 833 | P2: 250 | Q2: 0 | R2: 5551 | S2: 0 | T2: 694 | U2: 3000 | V2: 1147 | W2: - | X2: - | Y2: - | Z2: - | AA2: 594 | AB2: 495 | AC2: 15711 | AD2: -5811 | AE2: -0.5869697
A3: 2024-01 | B3: EduKids Brasil | C3: Validação | D3: 9900 | E3: 2 | F3: 19800 | G3: 0 | H3: 17 | I3: 60 | J3: 43 | K3: 0 | L3: 0 | M3: 944 | N3: 3125 | O3: 833 | P3: 250 | Q3: 0 | R3: 6588 | S3: 0 | T3: 347 | U3: 1500 | V3: 996 | W3: - | X3: - | Y3: - | Z3: - | AA3: 1188 | AB3: 990 | AC3: 16761 | AD3: 3039 | AE3: 0.15348485
A4: 2024-02 | B4: Clínica da Cidade | C4: Validação | D4: 9900 | E4: 1 | F4: 9900 | G4: 0 | H4: 8 | I4: 29 | J4: 14 | K4: 0 | L4: 0 | M4: 906 | N4: 2060 | O4: 833 | P4: 250 | Q4: 0 | R4: 5706 | S4: 0 | T4: 694 | U4: 3000 | V4: 955 | W4: - | X4: - | Y4: - | Z4: - | AA4: 594 | AB4: 495 | AC4: 15493 | AD4: -5593 | AE4: -0.56494949
A5: 2024-03 | B5: Cogni Academy | C5: Validação | D5: 9900 | E5: 2 | F5: 19800 | G5: 0 | H5: 16 | I5: 57 | J5: 43 | K5: 0 | L5: 0 | M5: 1018 | N5: 3125 | O5: 833 | P5: 250 | Q5: 0 | R5: 6238 | S5: 0 | T5: 347 | U5: 1500 | V5: 1074 | W5: - | X5: - | Y5: - | Z5: - | AA5: 1188 | AB5: 990 | AC5: 16563 | AD5: 3237 | AE5: 0.16348485
A6: 2024-03 | B6: Clínica da Cidade | C6: Validação | D6: 9900 | E6: 1 | F6: 9900 | G6: 0 | H6: 7 | I6: 33 | J6: 26 | K6: 0 | L6: 0 | M6: 924 | N6: 2344 | O6: 833 | P6: 250 | Q6: 0 | R6: 5797 | S6: 0 | T6: 694 | U6: 3000 | V6: 975 | W6: - | X6: - | Y6: - | Z6: - | AA6: 594 | AB6: 495 | AC6: 15906 | AD6: -6006 | AE6: -0.60666667
A7: 2024-06 | B7: Cogni Academy | C7: Validação | D7: 9900 | E7: 1 | F7: 9900 | G7: 0 | H7: 9 | I7: 32 | J7: 22 | K7: 0 | L7: 0 | M7: 927 | N7: 2273 | O7: 833 | P7: 250 | Q7: 0 | R7: 5711 | S7: 0 | T7: 694 | U7: 3000 | V7: 978 | W7: - | X7: - | Y7: - | Z7: - | AA7: 594 | AB7: 495 | AC7: 15755 | AD7: -5855 | AE7: -0.59141414
A8: 2024-06 | B8: Smart Nutri | C8: Validação | D8: 9900 | E8: 1 | F8: 9900 | G8: 0 | H8: 8 | I8: 32 | J8: 7 | K8: 0 | L8: 0 | M8: 1057 | N8: 2273 | O8: 833 | P8: 250 | Q8: 0 | R8: 5215 | S8: 0 | T8: 694 | U8: 3000 | V8: 1115 | W8: - | X8: - | Y8: - | Z8: - | AA8: 594 | AB8: 495 | AC8: 15526 | AD8: -5626 | AE8: -0.56828283
A9: 2024-06 | B9: EduKids Brasil | C9: Validação | D9: 9900 | E9: 1 | F9: 9900 | G9: 0 | H9: 8 | I9: 33 | J9: 27 | K9: 0 | L9: 0 | M9: 972 | N9: 2344 | O9: 833 | P9: 250 | Q9: 0 | R9: 5289 | S9: 0 | T9: 694 | U9: 3000 | V9: 1026 | W9: - | X9: - | Y9: - | Z9: - | AA9: 594 | AB9: 495 | AC9: 15497 | AD9: -5597 | AE9: -0.56535354
A10: 2024-07 | B10: Cogni Academy | C10: Validação | D10: 9900 | E10: 2 | F10: 19800 | G10: 0 | H10: 17 | I10: 59 | J10: 27 | K10: 0 | L10: 0 | M10: 996 | N10: 3125 | O10: 833 | P10: 250 | Q10: 0 | R10: 6498 | S10: 0 | T10: 347 | U10: 1500 | V10: 1051 | W10: - | X10: - | Y10: - | Z10: - | AA10: 1188 | AB10: 990 | AC10: 16778 | AD10: 3022 | AE10: 0.15262626
A11: 2024-07 | B11: Smart Nutri | C11: Validação | D11: 9900 | E11: 1 | F11: 9900 | G11: 0 | H11: 8 | I11: 31 | J11: 15 | K11: 0 | L11: 0 | M11: 1072 | N11: 2202 | O11: 833 | P11: 250 | Q11: 0 | R11: 5609 | S11: 0 | T11: 694 | U11: 3000 | V11: 1131 | W11: - | X11: - | Y11: - | Z11: - | AA11: 594 | AB11: 495 | AC11: 15880 | AD11: -5980 | AE11: -0.6040404
A12: 2024-07 | B12: EduKids Brasil | C12: Validação | D12: 9900 | E12: 1 | F12: 9900 | G12: 0 | H12: 8 | I12: 30 | J12: 27 | K12: 0 | L12: 0 | M12: 924 | N12: 2131 | O12: 833 | P12: 250 | Q12: 0 | R12: 5499 | S12: 0 | T12: 694 | U12: 3000 | V12: 974 | W12: - | X12: - | Y12: - | Z12: - | AA12: 594 | AB12: 495 | AC12: 15394 | AD12: -5494 | AE12: -0.55494949
A13: 2024-08 | B13: Cogni Academy | C13: Validação | D13: 9900 | E13: 1 | F13: 9900 | G13: 0 | H13: 9 | I13: 31 | J13: 28 | K13: 0 | L13: 0 | M13: 919 | N13: 2202 | O13: 833 | P13: 250 | Q13: 0 | R13: 5869 | S13: 0 | T13: 694 | U13: 3000 | V13: 970 | W13: - | X13: - | Y13: - | Z13: - | AA13: 594 | AB13: 495 | AC13: 15826 | AD13: -5926 | AE13: -0.59858586
... A27: 2024-12 | B27: EduKids Brasil | C27: Validação | D27: 9900 | E27: 1 | F27: 9900 | G27: 0 | H27: 8 | I27: 32 | J27: 7 | K27: 0 | L27: 0 | M27: 1035 | N27: 2273 | O27: 833 | P27: 250 | Q27: 0 | R27: 5818 | S27: 0 | T27: 694 | U27: 3000 | V27: 1092 | W27: - | X27: - | Y27: - | Z27: - | AA27: 594 | AB27: 495 | AC27: 16084 | AD27: -6184 | AE27: -0.62464646

Sheet 4_Base_Regressao
A1: Mês | B1: Franquia | C1: Tipo_Servico | D1: Receita_Total | E1: Qtd_Contratos | F1: H_Total | G1: H_Advogado | H1: Total_Custos | I1: Margem_RS | J1: Margem_PCT | K1: Num_Mes
A2: 2024-01 | B2: Clínica da Cidade | C2: Expansão | D2: 40000 | E2: 4 | F2: 213 | G2: 0 | H2: 12538 | I2: 27462 | J2: 0.68655 | K2: 1
A3: 2024-01 | B3: Cogni Academy | C3: Expansão | D3: 21600 | E3: 4 | F3: 193 | G3: 0 | H3: 10233 | I3: 11367 | J3: 0.52625 | K3: 1
A4: 2024-01 | B4: EduKids Brasil | C4: Expansão | D4: 32000 | E4: 4 | F4: 197 | G4: 0 | H4: 12347 | I4: 19653 | J4: 0.61415625 | K4: 1
A5: 2024-01 | B5: Smart Nutri | C5: Expansão | D5: 40000 | E5: 4 | F5: 192 | G5: 0 | H5: 12247 | I5: 27753 | J5: 0.693825 | K5: 1
A6: 2024-02 | B6: Clínica da Cidade | C6: Expansão | D6: 18000 | E6: 4 | F6: 207 | G6: 0 | H6: 10378 | I6: 7622 | J6: 0.42344444 | K6: 2
A7: 2024-02 | B7: Cogni Academy | C7: Expansão | D7: 32000 | E7: 4 | F7: 205 | G7: 0 | H7: 11567 | I7: 20433 | J7: 0.63853125 | K7: 2
A8: 2024-02 | B8: EduKids Brasil | C8: Expansão | D8: 18000 | E8: 4 | F8: 210 | G8: 0 | H8: 9283 | I8: 8717 | J8: 0.48427778 | K8: 2
A9: 2024-02 | B9: Smart Nutri | C9: Expansão | D9: 12000 | E9: 4 | F9: 213 | G9: 0 | H9: 9732 | I9: 2268 | J9: 0.189 | K9: 2
A10: 2024-03 | B10: Clínica da Cidade | C10: Expansão | D10: 18000 | E10: 4 | F10: 187 | G10: 0 | H10: 9619 | I10: 8381 | J10: 0.46561111 | K10: 3
A11: 2024-03 | B11: Cogni Academy | C11: Expansão | D11: 22500 | E11: 5 | F11: 221 | G11: 0 | H11: 10089 | I11: 12411 | J11: 0.5516 | K11: 3
A12: 2024-03 | B12: EduKids Brasil | C12: Expansão | D12: 12000 | E12: 4 | F12: 211 | G12: 0 | H12: 9911 | I12: 2089 | J12: 0.17408333 | K12: 3
A13: 2024-03 | B13: Smart Nutri | C13: Expansão | D13: 27000 | E13: 5 | F13: 229 | G13: 0 | H13: 11343 | I13: 15657 | J13: 0.57988889 | K13: 3
... A97: 2024-12 | B97: Smart Nutri | C97: Formatação | D97: 103500 | E97: 1 | F97: 104 | G97: 28 | H97: 39262 | I97: 64238 | J97: 0.620657 | K97: 12
A98: 2024-01 | B98: Clínica da Cidade | C98: Validação | D98: 9900 | E98: 1 | F98: 41 | G98: 0 | H98: =Planilha1!AC2 -> 15711 | I98: =Planilha1!AD2 -> -5811 | J98: =Planilha1!AE2 -> -0.5869697 | K98: 1
A99: 2024-01 | B99: EduKids Brasil | C99: Validação | D99: 19800 | E99: 2 | F99: 103 | G99: 0 | H99: =Planilha1!AC3 -> 16761 | I99: =Planilha1!AD3 -> 3039 | J99: =Planilha1!AE3 -> 0.15348485 | K99: 1
A100: 2024-02 | B100: Clínica da Cidade | C100: Validação | D100: 9900 | E100: 1 | F100: 43 | G100: 0 | H100: =Planilha1!AC4 -> 15493 | I100: =Planilha1!AD4 -> -5593 | J100: =Planilha1!AE4 -> -0.56494949 | K100: 2
A101: 2024-03 | B101: Clínica da Cidade | C101: Validação | D101: 9900 | E101: 1 | F101: 100 | G101: 0 | H101: =Planilha1!AC5 -> 16563 | I101: =Planilha1!AD5 -> 3237 | J101: =Planilha1!AE5 -> 0.16348485 | K101: 3
A102: 2024-03 | B102: Cogni Academy | C102: Validação | D102: 19800 | E102: 2 | F102: 59 | G102: 0 | H102: =Planilha1!AC6 -> 15906 | I102: =Planilha1!AD6 -> -6006 | J102: =Planilha1!AE6 -> -0.60666667 | K102: 3
A103: 2024-06 | B103: Cogni Academy | C103: Validação | D103: 9900 | E103: 1 | F103: 54 | G103: 0 | H103: =Planilha1!AC7 -> 15755 | I103: =Planilha1!AD7 -> -5855 | J103: =Planilha1!AE7 -> -0.59141414 | K103: 6
A104: 2024-06 | B104: EduKids Brasil | C104: Validação | D104: 9900 | E104: 1 | F104: 39 | G104: 0 | H104: =Planilha1!AC8 -> 15526 | I104: =Planilha1!AD8 -> -5626 | J104: =Planilha1!AE8 -> -0.56828283 | K104: 6
A105: 2024-06 | B105: Smart Nutri | C105: Validação | D105: 9900 | E105: 1 | F105: 60 | G105: 0 | H105: =Planilha1!AC9 -> 15497 | I105: =Planilha1!AD9 -> -5597 | J105: =Planilha1!AE9 -> -0.56535354 | K105: 6
A106: 2024-07 | B106: Cogni Academy | C106: Validação | D106: 19800 | E106: 2 | F106: 86 | G106: 0 | H106: =Planilha1!AC10 -> 16778 | I106: =Planilha1!AD10 -> 3022 | J106: =Planilha1!AE10 -> 0.15262626 | K106: 7
A107: 2024-07 | B107: EduKids Brasil | C107: Validação | D107: 9900 | E107: 1 | F107: 46 | G107: 0 | H107: =Planilha1!AC11 -> 15880 | I107: =Planilha1!AD11 -> -5980 | J107: =Planilha1!AE11 -> -0.6040404 | K107: 7
A108: 2024-07 | B108: Smart Nutri | C108: Validação | D108: 9900 | E108: 1 | F108: 57 | G108: 0 | H108: =Planilha1!AC12 -> 15394 | I108: =Planilha1!AD12 -> -5494 | J108: =Planilha1!AE12 -> -0.55494949 | K108: 7
A109: 2024-08 | B109: Clínica da Cidade | C109: Validação | D109: 9900 | E109: 1 | F109: 59 | G109: 0 | H109: =Planilha1!AC13 -> 15826 | I109: =Planilha1!AD13 -> -5926 | J109: =Planilha1!AE13 -> -0.59858586 | K109: 8
... A123: 2024-12 | B123: Smart Nutri | C123: Validação | D123: 9900 | E123: 1 | F123: 39 | G123: 0 | H123: =Planilha1!AC27 -> 16084 | I123: =Planilha1!AD27 -> -6184 | J123: =Planilha1!AE27 -> -0.62464646 | K123: 12

Sheet Planilha2
A1: RESUMO DOS RESULTADOS
A3: Estatística de regressão
A4: R múltiplo | B4: 0.53498768
A5: R-Quadrado | B5: 0.28621182
A6: R-quadrado ajustado | B6: 0.22414328
A7: Erro padrão | B7: 561.70981
A8: Observações | B8: 26
A10: ANOVA
B11: gl | C11: SQ | D11: MQ | E11: F | F11: F de significação
A12: Regressão | B12: 2 | C12: 2909846.4 | D12: 1454923.2 | E12: 4.6112223 | F12: 0.02070368
A13: Resíduo | B13: 23 | C13: 7256911.9 | D13: 315517.91
A14: Total | B14: 25 | C14: 10166758
B16: Coeficientes | C16: Erro padrão | D16: Stat t | E16: valor-P | F16: 95% inferiores | G16: 95% superiores | H16: Inferior 90,0% | I16: Superior 90,0%
A17: Interseção | B17: 8962.6753 | C17: 364.13393 | D17: 24.613678 | E17: 5.0176891e-18 | F17: 8209.4068 | G17: 9715.9437 | H17: 8338.5965 | I17: 9586.754
A18: QTD_Contratos | B18: -753.44876 | C18: 1737.1296 | D18: -0.43373205 | E18: 0.6685242 | F18: -4346.9751 | G18: 2840.0775 | H18: -3730.6657 | I18: 2223.7682
A19: H_total | B19: 53.936615 | C19: 59.159352 | D19: 0.91171748 | E19: 0.37137491 | F19: -68.443828 | G19: 176.31706 | H19: -47.454914 | I19: 155.32814
A23: RESULTADOS DE RESÍDUOS
A25: Observação | B25: Previsto(a) Tot_Custos | C25: Resíduos | D25: Resíduos padrão
A26: 1 | B26: 9773.3883 | C26: -173.38834 | D26: -0.32182069
A27: 2 | B27: 10691.975 | C27: -443.97465 | D27: -0.8240475
A28: 3 | B28: 9773.3883 | C28: -638.38834 | D28: -1.1848927
A29: 4 | B29: 10530.165 | C29: -76.1648 | D29: -0.14136711
A30: 5 | B30: 9989.1348 | C30: -597.1348 | D30: -1.1083233
A31: 6 | B31: 9935.1982 | C31: -567.19818 | D31: -1.0527589
A32: 7 | B32: 9935.1982 | C32: 1163.8018 | D32: 2.1600963
A33: 8 | B33: 9989.1348 | C33: 704.8652 | D33: 1.3082783
A34: 9 | B34: 10638.038 | C34: 542.96197 | D34: 1.0077748
A35: 10 | B35: 9881.2616 | C35: 759.73843 | D35: 1.4101268
A36: 11 | B36: 9827.325 | C36: -400.32495 | D36: -0.74303067
A37: 12 | B37: 9881.2616 | C37: -264.26157 | D37: -0.49048766
... A51: 26 | B51: 9935.1982 | C51: 46.801817 | D51: 0.086867394

Sheet Planilha11
A1: RESUMO DOS RESULTADOS
A3: Estatística de regressão
A4: R múltiplo | B4: 0.68019971
A5: R-Quadrado | B5: 0.46267165
A6: R-quadrado ajustado | B6: 0.43708458
A7: Erro padrão | B7: 436.82917
A8: Observações | B8: 23
A10: ANOVA
B11: gl | C11: SQ | D11: MQ | E11: F | F11: F de significação
A12: Regressão | B12: 1 | C12: 3450449.6 | D12: 3450449.6 | E12: 18.082248 | F12: 0.00035539037
A13: Resíduo | B13: 21 | C13: 4007214.3 | D13: 190819.73
A14: Total | B14: 22 | C14: 7457663.9
B16: Coeficientes | C16: Erro padrão | D16: Stat t | E16: valor-P | F16: 95% inferiores | G16: 95% superiores | H16: Inferior 90,0% | I16: Superior 90,0%
A17: Interseção | B17: 8865.9661 | C17: 259.93669 | D17: 34.108175 | E17: 7.0941598e-20 | F17: 8325.3982 | G17: 9406.534 | H17: 8418.6819 | I17: 9313.2503
A18: Tot_horas | B18: 14.725281 | C18: 3.4628795 | D18: 4.2523227 | E18: 0.00035539037 | F18: 7.5238289 | G18: 21.926733 | H18: 8.7665558 | I18: 20.684007
A22: RESULTADOS DE RESÍDUOS
A24: Observação | B24: Previsto(a) Total Custos | C24: Resíduos | D24: Resíduos padrão
A25: 1 | B25: 9572.7796 | C25: 27.220401 | D25: 0.06378001
A26: 2 | B26: 10633 | C26: -384.99984 | D26: -0.90209154
A27: 3 | B27: 9616.9554 | C27: -481.95544 | D27: -1.1292678
A28: 4 | B28: 10574.099 | C28: -120.09872 | D28: -0.28140281
A29: 5 | B29: 9837.8347 | C29: -445.83466 | D29: -1.0446333
A30: 6 | B30: 9793.6588 | C30: -425.65882 | D30: -0.99735941
A31: 7 | B31: 9867.2852 | C31: 826.71478 | D31: 1.937072
A32: 8 | B32: 10382.67 | C32: 798.32994 | D32: 1.8705636
A33: 9 | B33: 9661.1313 | C33: 979.86871 | D33: 2.2959263
A34: 10 | B34: 9823.1094 | C34: -396.10938 | D34: -0.92812225
A35: 11 | B35: 9867.2852 | C35: -250.28522 | D35: -0.58644227
A36: 12 | B36: 9631.6807 | C36: 266.31928 | D36: 0.6240116
... A47: 23 | B47: 9558.0543 | C47: 423.94568 | D47: 0.99334538

Sheet Planilha17
A1: RESUMO DOS RESULTADOS
A3: Estatística de regressão
A4: R múltiplo | B4: 0.69076629
A5: R-Quadrado | B5: 0.47715807
A6: R-quadrado ajustado | B6: 0.39460408
A7: Erro padrão | B7: 477.71836
A8: Observações | B8: 23
A10: ANOVA
B11: gl | C11: SQ | D11: MQ | E11: F | F11: F de significação
A12: Regressão | B12: 3 | C12: 3957212.1 | D12: 1319070.7 | E12: 5.7799518 | F12: 0.0055323145
A13: Resíduo | B13: 19 | C13: 4336081.7 | D13: 228214.83
A14: Total | B14: 22 | C14: 8293293.8
B16: Coeficientes | C16: Erro padrão | D16: Stat t | E16: valor-P | F16: 95% inferiores | G16: 95% superiores | H16: Inferior 90,0% | I16: Superior 90,0%
A17: Interseção | B17: 8586.1967 | C17: 345.18724 | D17: 24.874027 | E17: 5.8476089e-16 | F17: 7863.7115 | G17: 9308.6819 | H17: 7989.3221 | I17: 9183.0713
A18: H_Cons | B18: 74.789953 | C18: 36.082073 | D18: 2.0727731 | E18: 0.052039414 | F18: -0.73069495 | G18: 150.3106 | H18: 12.399256 | I18: 137.18065
A19: H_GP | B19: -2.0799145 | C19: 12.75216 | D19: -0.16310291 | E19: 0.87215972 | F19: -28.770493 | G19: 24.610664 | H19: -24.130094 | I19: 19.970265
A20: H_Vend | B20: -138.03376 | C20: 121.83819 | D20: -1.1329269 | E20: 0.27133961 | F20: -393.04402 | G20: 116.9765 | H20: -348.70817 | I20: 72.640652
A24: RESULTADOS DE RESÍDUOS
A26: Observação | B26: Previsto(a) Total Custos | C26: Resíduos | D26: Resíduos padrão
A27: 1 | B27: 9763.9101 | C27: -163.91005 | D27: -0.36920553
A28: 2 | B28: 10637.584 | C28: -389.58366 | D28: -0.87753276
A29: 3 | B29: 9621.7165 | C29: -486.71647 | D29: -1.0963233
A30: 4 | B30: 10551.248 | C30: -97.247555 | D30: -0.21904901
A31: 5 | B31: 10033.951 | C31: -641.95106 | D31: -1.4459875
A32: 6 | B32: 9691.4132 | C32: -323.41325 | D32: -0.72848467
A33: 7 | B33: 9893.8374 | C33: 800.16261 | D33: 1.8023572
A34: 8 | B34: 10596.072 | C34: 584.92767 | D34: 1.3175429
A35: 9 | B35: 9769.2165 | C35: 871.78354 | D35: 1.9636825
A36: 10 | B36: 9669.4675 | C36: -242.46753 | D36: -0.54615536
A37: 11 | B37: 9604.1438 | C37: 12.85619 | D37: 0.028958421
A38: 12 | B38: 9542.7667 | C38: 355.23332 | D38: 0.80015901
... A49: 23 | B49: 9860.6457 | C49: 121.35427 | D49: 0.27334913
J56: Qtd | K56: C_Agenc | N56: Qtd | O56: C_Agenc
I57: =J57=N57 -> TRUE | J57: 4 | K57: 8451 | N57: 4 | O57: 8501
I58: =J58=N58 -> TRUE | J58: 1 | K58: 5417 | N58: 1 | O58: 5102
I59: =J59=N59 -> TRUE | J59: 4 | K59: 8383 | N59: 4 | O59: 8933
I60: =J60=N60 -> TRUE | J60: 1 | K60: 5938 | N60: 1 | O60: 5450
I61: =J61=N61 -> TRUE | J61: 1 | K61: 5551 | N61: 1 | O61: 5200
I62: =J62=N62 -> TRUE | J62: 4 | K62: 8815 | N62: 4 | O62: 8111
I63: =J63=N63 -> TRUE | J63: 1 | K63: 5903 | N63: 1 | O63: 5888
...

Sheet REG_VAL
A1: QTD_Contratos | B1: H_total | C1: Tot_Custos | D1: Margem_R$ | E1: Margem_PCT | F1: NUM_MÊS
A2: 1 | B2: 29 | C2: 9600 | D2: 300 | E2: 0.0303 | F2: 1
A3: 2 | B3: 60 | C3: 10248 | D3: 9552 | E3: 0.4824 | F3: 1
A4: 1 | B4: 29 | C4: 9135 | D4: 765 | E4: 0.0773 | F4: 2
A5: 2 | B5: 57 | C5: 10454 | D5: 9346 | E5: 0.472 | F5: 3
A6: 1 | B6: 33 | C6: 9392 | D6: 508 | E6: 0.0513 | F6: 3
A7: 1 | B7: 32 | C7: 9368 | D7: 532 | E7: 0.0537 | F7: 6
A8: 1 | B8: 32 | C8: 11099 | D8: -1199 | E8: -0.1211 | F8: 6
A9: 1 | B9: 33 | C9: 10694 | D9: -794 | E9: -0.0802 | F9: 6
A10: 2 | B10: 59 | C10: 11181 | D10: 8619 | E10: 0.4353 | F10: 7
A11: 1 | B11: 31 | C11: 10641 | D11: -741 | E11: -0.0748 | F11: 7
A12: 1 | B12: 30 | C12: 9427 | D12: 473 | E12: 0.0478 | F12: 7
A13: 1 | B13: 31 | C13: 9617 | D13: 283 | E13: 0.0286 | F13: 8
... A27: 1 | B27: 32 | C27: 9982 | D27: -82 | E27: -0.0083 | F27: 12
A33: NUM_MÊS | B33: Qtd | C33: H_Cons | D33: H_GP | E33: H_Vend | F33: Total Custos | G33: C_Vend | H33: C_Cons | I33: C_Agenc | J33: C_GP | K33: C_Tec | L33: C_Imp | M33: C_Com | N33: Total Custos | O33: Margem R$ | P33: Margem %
A34: 1 | B34: 1 | C34: 29 | D34: 12 | E34: 7 | F34: 9600 | G34: 1087 | H34: 2060 | I34: 1217 | J34: 3000 | K34: 1147 | L34: 594 | M34: 495 | N34: 9600 | O34: 300 | P34: 0.0303
A35: 1 | B35: 2 | C35: 60 | D35: 43 | E35: 17 | F35: 10248 | G35: 944 | H35: 3125 | I35: 1505 | J35: 1500 | K35: 996 | L35: 1188 | M35: 990 | N35: 10248 | O35: 9552 | P35: 0.4824
A36: 2 | B36: 1 | C36: 29 | D36: 14 | E36: 8 | F36: 9135 | G36: 906 | H36: 2060 | I36: 1125 | J36: 3000 | K36: 955 | L36: 594 | M36: 495 | N36: 9135 | O36: 765 | P36: 0.0773
A37: 3 | B37: 2 | C37: 57 | D37: 43 | E37: 16 | F37: 10454 | G37: 1018 | H37: 3125 | I37: 1559 | J37: 1500 | K37: 1074 | L37: 1188 | M37: 990 | N37: 10454 | O37: 9346 | P37: 0.472
A38: 3 | B38: 1 | C38: 33 | D38: 26 | E38: 7 | F38: 9392 | G38: 924 | H38: 2344 | I38: 1060 | J38: 3000 | K38: 975 | L38: 594 | M38: 495 | N38: 9392 | O38: 508 | P38: 0.0513
A39: 6 | B39: 1 | C39: 32 | D39: 22 | E39: 9 | F39: 9368 | G39: 927 | H39: 2273 | I39: 1101 | J39: 3000 | K39: 978 | L39: 594 | M39: 495 | N39: 9368 | O39: 532 | P39: 0.0537
A40: 6 | B40: 1 | C40: 33 | D40: 27 | E40: 8 | F40: 10694 | G40: 972 | H40: 2344 | I40: 2263 | J40: 3000 | K40: 1026 | L40: 594 | M40: 495 | N40: 10694 | O40: -794 | P40: -0.0802
A41: 7 | B41: 2 | C41: 59 | D41: 27 | E41: 17 | F41: 11181 | G41: 996 | H41: 3125 | I41: 2331 | J41: 1500 | K41: 1051 | L41: 1188 | M41: 990 | N41: 11181 | O41: 8619 | P41: 0.4353
A42: 7 | B42: 1 | C42: 31 | D42: 15 | E42: 8 | F42: 10641 | G42: 1072 | H42: 2202 | I42: 2147 | J42: 3000 | K42: 1131 | L42: 594 | M42: 495 | N42: 10641 | O42: -741 | P42: -0.0748
A43: 7 | B43: 1 | C43: 30 | D43: 27 | E43: 8 | F43: 9427 | G43: 924 | H43: 2131 | I43: 1309 | J43: 3000 | K43: 974 | L43: 594 | M43: 495 | N43: 9427 | O43: 473 | P43: 0.0478
A44: 8 | B44: 1 | C44: 31 | D44: 28 | E44: 9 | F44: 9617 | G44: 919 | H44: 2202 | I44: 1437 | J44: 3000 | K44: 970 | L44: 594 | M44: 495 | N44: 9617 | O44: 283 | P44: 0.0286
A45: 8 | B45: 1 | C45: 28 | D45: 16 | E45: 8 | F45: 9898 | G45: 1008 | H45: 1989 | I45: 1749 | J45: 3000 | K45: 1063 | L45: 594 | M45: 495 | N45: 9898 | O45: 2 | P45: 0.0002
... A56: 12 | B56: 1 | C56: 32 | D56: 7 | E56: 8 | F56: 9982 | G56: 1035 | H56: 2273 | I56: 1493 | J56: 3000 | K56: 1092 | L56: 594 | M56: 495 | N56: 9982 | O56: -82 | P56: -0.0083
N57: =AVERAGE(O34:O56) -> 2106.2609 | O57: =AVERAGE(P34:P56) -> 0.11251739
A66: NUM_MÊS | B66: Qtd | C66: H_Cons | D66: H_GP | E66: H_Vend | F66: Total Custos | G66: C_Vend | H66: C_Cons | I66: C_Agenc | J66: C_GP | K66: C_Tec | L66: C_Imp | M66: C_Com | N66: Total Custos | O66: Margem R$ | P66: Margem %
A67: 1 | B67: 1 | C67: 29 | D67: 12 | E67: 7 | F67: 9600 | G67: 1087 | H67: 2060 | I67: 1217 | J67: 3000 | K67: 1147 | L67: 594 | M67: 495 | N67: =SUM(G67:M67) -> 9600 | O67: 300 | P67: 0.0303
A68: 1 | B68: 2 | C68: 60 | D68: 43 | E68: 17 | F68: 10248 | G68: 944 | H68: 3125 | I68: 1505 | J68: 1500 | K68: 996 | L68: 1188 | M68: 990 | N68: =SUM(G68:M68) -> 10248 | O68: 9552 | P68: 0.4824
A69: 2 | B69: 1 | C69: 29 | D69: 14 | E69: 8 | F69: 9135 | G69: 906 | H69: 2060 | I69: 1125 | J69: 3000 | K69: 955 | L69: 594 | M69: 495 | N69: =SUM(G69:M69) -> 9135 | O69: 765 | P69: 0.0773
A70: 3 | B70: 2 | C70: 57 | D70: 43 | E70: 16 | F70: 10454 | G70: 1018 | H70: 3125 | I70: 1559 | J70: 1500 | K70: 1074 | L70: 1188 | M70: 990 | N70: =SUM(G70:M70) -> 10454 | O70: 9346 | P70: 0.472
A71: 3 | B71: 1 | C71: 33 | D71: 26 | E71: 7 | F71: 9392 | G71: 924 | H71: 2344 | I71: 1060 | J71: 3000 | K71: 975 | L71: 594 | M71: 495 | N71: =SUM(G71:M71) -> 9392 | O71: 508 | P71: 0.0513
A72: 6 | B72: 1 | C72: 32 | D72: 22 | E72: 9 | F72: 9368 | G72: 927 | H72: 2273 | I72: 1101 | J72: 3000 | K72: 978 | L72: 594 | M72: 495 | N72: =SUM(G72:M72) -> 9368 | O72: 532 | P72: 0.0537
A73: 6 | B73: 1 | C73: 32 | D73: 7 | E73: 8 | F73: 11099 | G73: 1057 | H73: 2273 | I73: 2565 | J73: 3000 | K73: 1115 | L73: 594 | M73: 495 | N73: =SUM(G73:M73) -> 11099 | O73: -1199 | P73: -0.1211
A74: 6 | B74: 1 | C74: 33 | D74: 27 | E74: 8 | F74: 10694 | G74: 972 | H74: 2344 | I74: 2263 | J74: 3000 | K74: 1026 | L74: 594 | M74: 495 | N74: =SUM(G74:M74) -> 10694 | O74: -794 | P74: -0.0802
A75: 7 | B75: 2 | C75: 59 | D75: 27 | E75: 17 | F75: 11181 | G75: 996 | H75: 3125 | I75: 2331 | J75: 1500 | K75: 1051 | L75: 1188 | M75: 990 | N75: =SUM(G75:M75) -> 11181 | O75: 8619 | P75: 0.4353
A76: 7 | B76: 1 | C76: 31 | D76: 15 | E76: 8 | F76: 10641 | G76: 1072 | H76: 2202 | I76: 2147 | J76: 3000 | K76: 1131 | L76: 594 | M76: 495 | N76: =SUM(G76:M76) -> 10641 | O76: -741 | P76: -0.0748
...
